[2024-08-29T11:29:38.291+0200] {taskinstance.py:1090} INFO - Dependencies all met for dep_context=non-requeueable deps ti=<TaskInstance: executing_sql_pipeline.update_values manual__2024-08-29T09:29:28.012117+00:00 [queued]>
[2024-08-29T11:29:38.297+0200] {taskinstance.py:1090} INFO - Dependencies all met for dep_context=requeueable deps ti=<TaskInstance: executing_sql_pipeline.update_values manual__2024-08-29T09:29:28.012117+00:00 [queued]>
[2024-08-29T11:29:38.297+0200] {taskinstance.py:1288} INFO - 
--------------------------------------------------------------------------------
[2024-08-29T11:29:38.297+0200] {taskinstance.py:1289} INFO - Starting attempt 1 of 1
[2024-08-29T11:29:38.297+0200] {taskinstance.py:1290} INFO - 
--------------------------------------------------------------------------------
[2024-08-29T11:29:38.303+0200] {taskinstance.py:1309} INFO - Executing <Task(SqliteOperator): update_values> on 2024-08-29 09:29:28.012117+00:00
[2024-08-29T11:29:38.312+0200] {standard_task_runner.py:55} INFO - Started process 189 to run task
[2024-08-29T11:29:38.316+0200] {standard_task_runner.py:82} INFO - Running: ['airflow', 'tasks', 'run', 'executing_sql_pipeline', 'update_values', 'manual__2024-08-29T09:29:28.012117+00:00', '--job-id', '78', '--raw', '--subdir', 'DAGS_FOLDER/create_sql_pipeline.py', '--cfg-path', '/var/folders/q3/lf85n5dd03zdfbv5xqcw4__40000gn/T/tmpm94newrg']
[2024-08-29T11:29:38.317+0200] {standard_task_runner.py:83} INFO - Job 78: Subtask update_values
[2024-08-29T11:29:38.405+0200] {task_command.py:389} INFO - Running <TaskInstance: executing_sql_pipeline.update_values manual__2024-08-29T09:29:28.012117+00:00 [running]> on host roselinas-mbp
[2024-08-29T11:29:38.431+0200] {taskinstance.py:1518} INFO - Exporting the following env vars:
AIRFLOW_CTX_DAG_OWNER=Roselina_m
AIRFLOW_CTX_DAG_ID=executing_sql_pipeline
AIRFLOW_CTX_TASK_ID=update_values
AIRFLOW_CTX_EXECUTION_DATE=2024-08-29T09:29:28.012117+00:00
AIRFLOW_CTX_TRY_NUMBER=1
AIRFLOW_CTX_DAG_RUN_ID=manual__2024-08-29T09:29:28.012117+00:00
[2024-08-29T11:29:38.431+0200] {sql.py:254} INFO - Executing: 
            UPDATE users SET city = 'Seattle';
        
[2024-08-29T11:29:38.434+0200] {base.py:73} INFO - Using connection ID 'my_sqlite_conn' for task execution.
[2024-08-29T11:29:38.478+0200] {base.py:73} INFO - Using connection ID 'my_sqlite_conn' for task execution.
[2024-08-29T11:29:38.479+0200] {sql.py:375} INFO - Running statement: 
            UPDATE users SET city = 'Seattle';
        , parameters: None
[2024-08-29T11:29:38.479+0200] {taskinstance.py:1776} ERROR - Task failed with exception
Traceback (most recent call last):
  File "/Users/roselina/opt/anaconda3/envs/python37/lib/python3.7/site-packages/airflow/providers/common/sql/operators/sql.py", line 266, in execute
    **extra_kwargs,
  File "/Users/roselina/opt/anaconda3/envs/python37/lib/python3.7/site-packages/airflow/providers/common/sql/hooks/sql.py", line 349, in run
    self._run_command(cur, sql_statement, parameters)
  File "/Users/roselina/opt/anaconda3/envs/python37/lib/python3.7/site-packages/airflow/providers/common/sql/hooks/sql.py", line 380, in _run_command
    cur.execute(sql_statement)
sqlite3.OperationalError: no such column: city
[2024-08-29T11:29:38.482+0200] {taskinstance.py:1332} INFO - Marking task as FAILED. dag_id=executing_sql_pipeline, task_id=update_values, execution_date=20240829T092928, start_date=20240829T092938, end_date=20240829T092938
[2024-08-29T11:29:38.486+0200] {standard_task_runner.py:105} ERROR - Failed to execute job 78 for task update_values (no such column: city; 189)
[2024-08-29T11:29:38.509+0200] {local_task_job.py:212} INFO - Task exited with return code 1
[2024-08-29T11:29:38.559+0200] {taskinstance.py:2596} INFO - 0 downstream tasks scheduled from follow-on schedule check
